Workbook

Sheet Dashboard
A1: PRE-CONVERT TRACKING DASHBOARD — GMES Conversion (34 page)
A4: Progress Overview
A5: Total | B5: 34
A6: Overall Status breakdown
A7: Overall State | B7: page | C7: % total
A8: Backlog | B8: =COUNTIF(Tracking!N:N,"Backlog") | C8: =IFERROR(B8/34,0)
A9: Discovery | B9: =COUNTIF(Tracking!N:N,"Discovery") | C9: =IFERROR(B9/34,0)
A10: Data Requested | B10: =COUNTIF(Tracking!N:N,"Data Requested") | C10: =IFERROR(B10/34,0)
A11: Data Ready | B11: =COUNTIF(Tracking!N:N,"Data Ready") | C11: =IFERROR(B11/34,0)
A12: Converting | B12: =COUNTIF(Tracking!N:N,"Converting") | C12: =IFERROR(B12/34,0)
A13: QA | B13: =COUNTIF(Tracking!N:N,"QA") | C13: =IFERROR(B13/34,0)
A14: Done | B14: =COUNTIF(Tracking!N:N,"Done") | C14: =IFERROR(B14/34,0)
A15: TOTAL | B15: =SUM(B8:B14) | C15: =B15/34
A18: Statistics by Each Step (B1 → B6)
A19: Bước | B19: Checkpoint | C19: Not Started | D19: In Progress | E19: Done | F19: Blocked | G19: N/A | H19: % Done
A20: B1 | B20: Verify menu | C20: =COUNTIF(Tracking!G:G,"Not Started") | D20: =COUNTIF(Tracking!G:G,"In Progress") | E20: =COUNTIF(Tracking!G:G,"Done") | F20: =COUNTIF(Tracking!G:G,"Blocked") | G20: =COUNTIF(Tracking!G:G,"N/A") | H20: =IFERROR(E20/(34-G20),0)
A21: B2 | B21: Smoke-test page | C21: =COUNTIF(Tracking!H:H,"Not Started") | D21: =COUNTIF(Tracking!H:H,"In Progress") | E21: =COUNTIF(Tracking!H:H,"Done") | F21: =COUNTIF(Tracking!H:H,"Blocked") | G21: =COUNTIF(Tracking!H:H,"N/A") | H21: =IFERROR(E21/(34-G21),0)
A22: B3 | B22: Extract BizID | C22: =COUNTIF(Tracking!I:I,"Not Started") | D22: =COUNTIF(Tracking!I:I,"In Progress") | E22: =COUNTIF(Tracking!I:I,"Done") | F22: =COUNTIF(Tracking!I:I,"Blocked") | G22: =COUNTIF(Tracking!I:I,"N/A") | H22: =IFERROR(E22/(34-G22),0)
A23: B4 | B23: Trace to tables | C23: =COUNTIF(Tracking!J:J,"Not Started") | D23: =COUNTIF(Tracking!J:J,"In Progress") | E23: =COUNTIF(Tracking!J:J,"Done") | F23: =COUNTIF(Tracking!J:J,"Blocked") | G23: =COUNTIF(Tracking!J:J,"N/A") | H23: =IFERROR(E23/(34-G23),0)
A24: B5 | B24: Data request sent | C24: =COUNTIF(Tracking!K:K,"Not Started") | D24: =COUNTIF(Tracking!K:K,"In Progress") | E24: =COUNTIF(Tracking!K:K,"Done") | F24: =COUNTIF(Tracking!K:K,"Blocked") | G24: =COUNTIF(Tracking!K:K,"N/A") | H24: =IFERROR(E24/(34-G24),0)
A25: B6 | B25: Data received & OK | C25: =COUNTIF(Tracking!L:L,"Not Started") | D25: =COUNTIF(Tracking!L:L,"In Progress") | E25: =COUNTIF(Tracking!L:L,"Done") | F25: =COUNTIF(Tracking!L:L,"Blocked") | G25: =COUNTIF(Tracking!L:L,"N/A") | H25: =IFERROR(E25/(34-G25),0)
A28: Statistics by Business Phase
A29: Phase | B29: Name | C29: Total page | D29: Data Ready (B6 Done) | E29: Converting | F29: Done | G29: % Ready
A30: 1 | B30: Planning | C30: =COUNTIF(Tracking!B:B,1) | D30: =COUNTIFS(Tracking!B:B,1,Tracking!L:L,"Done") | E30: =COUNTIFS(Tracking!B:B,1,Tracking!N:N,"Converting") | F30: =COUNTIFS(Tracking!B:B,1,Tracking!N:N,"Done") | G30: =IFERROR(D30/C30,0)
A31: 2 | B31: Raw Material | C31: =COUNTIF(Tracking!B:B,2) | D31: =COUNTIFS(Tracking!B:B,2,Tracking!L:L,"Done") | E31: =COUNTIFS(Tracking!B:B,2,Tracking!N:N,"Converting") | F31: =COUNTIFS(Tracking!B:B,2,Tracking!N:N,"Done") | G31: =IFERROR(D31/C31,0)
A32: 3 | B32: Packaging | C32: =COUNTIF(Tracking!B:B,3) | D32: =COUNTIFS(Tracking!B:B,3,Tracking!L:L,"Done") | E32: =COUNTIFS(Tracking!B:B,3,Tracking!N:N,"Converting") | F32: =COUNTIFS(Tracking!B:B,3,Tracking!N:N,"Done") | G32: =IFERROR(D32/C32,0)
A33: 4 | B33: Scrap | C33: =COUNTIF(Tracking!B:B,4) | D33: =COUNTIFS(Tracking!B:B,4,Tracking!L:L,"Done") | E33: =COUNTIFS(Tracking!B:B,4,Tracking!N:N,"Converting") | F33: =COUNTIFS(Tracking!B:B,4,Tracking!N:N,"Done") | G33: =IFERROR(D33/C33,0)
A34: 5 | B34: Lot Trace | C34: =COUNTIF(Tracking!B:B,5) | D34: =COUNTIFS(Tracking!B:B,5,Tracking!L:L,"Done") | E34: =COUNTIFS(Tracking!B:B,5,Tracking!N:N,"Converting") | F34: =COUNTIFS(Tracking!B:B,5,Tracking!N:N,"Done") | G34: =IFERROR(D34/C34,0)
A35: 6 | B35: Production Results | C35: =COUNTIF(Tracking!B:B,6) | D35: =COUNTIFS(Tracking!B:B,6,Tracking!L:L,"Done") | E35: =COUNTIFS(Tracking!B:B,6,Tracking!N:N,"Converting") | F35: =COUNTIFS(Tracking!B:B,6,Tracking!N:N,"Done") | G35: =IFERROR(D35/C35,0)
A36: 7 | B36: Production Inquiry | C36: =COUNTIF(Tracking!B:B,7) | D36: =COUNTIFS(Tracking!B:B,7,Tracking!L:L,"Done") | E36: =COUNTIFS(Tracking!B:B,7,Tracking!N:N,"Converting") | F36: =COUNTIFS(Tracking!B:B,7,Tracking!N:N,"Done") | G36: =IFERROR(D36/C36,0)
A37: 8 | B37: Shipment | C37: =COUNTIF(Tracking!B:B,8) | D37: =COUNTIFS(Tracking!B:B,8,Tracking!L:L,"Done") | E37: =COUNTIFS(Tracking!B:B,8,Tracking!N:N,"Converting") | F37: =COUNTIFS(Tracking!B:B,8,Tracking!N:N,"Done") | G37: =IFERROR(D37/C37,0)
A38: 9 | B38: Warehouse | C38: =COUNTIF(Tracking!B:B,9) | D38: =COUNTIFS(Tracking!B:B,9,Tracking!L:L,"Done") | E38: =COUNTIFS(Tracking!B:B,9,Tracking!N:N,"Converting") | F38: =COUNTIFS(Tracking!B:B,9,Tracking!N:N,"Done") | G38: =IFERROR(D38/C38,0)
A39: 10 | B39: Board | C39: =COUNTIF(Tracking!B:B,10) | D39: =COUNTIFS(Tracking!B:B,10,Tracking!L:L,"Done") | E39: =COUNTIFS(Tracking!B:B,10,Tracking!N:N,"Converting") | F39: =COUNTIFS(Tracking!B:B,10,Tracking!N:N,"Done") | G39: =IFERROR(D39/C39,0)
A43: BLOCKERS
A44: • Số màn có ít nhất 1 checkpoint bị Blocked: | H44: =COUNTIF(Tracking!N4:N37,"Blocked")
A45: • Số màn đang bị idle | H45: =COUNTIFS(Tracking!K4:K37,"Done",Tracking!L4:L37,"In Progress")
A48: Last updated: | B48: =TODAY()

Sheet Detailed Plan
A1: No | B1: Menu Group Name(kor) | C1: Menu Group Name(eng) | D1: Module Group | E1: Screen ID | F1: Page name(Ko) | G1: Page (EN) | H1: Page (VN) | I1: Popup/Sub | J1: Status | K1: Assignee | L1: Start Date | M1: End Date | N1: Estimate (h) | O1: Note
A2: 6 | D2: GMES_IM_POM | F2: 알람전송 | G2: Alarm Transmission | H2: Truyền cảnh báo | I2: 0 | J2: TODO | O2: Source ASPX 없음 — 소스 확인 필요 (Source ASPX missing — needs confirmation)
A3: 18 | B3: 공정관리>측정관리 | C3: Process Management>측정관리 | D3: GMES_IM_POM | E3: GMES_IMES_0243 | F3: 공정운전정보 | G3: Process Operation Information | H3: Thông tin vận hành công đoạn | I3: 0 | J3: TODO | O3: The Webiste UI can not be access
A4: 24 | B4: 생산실적>실적조정 관리 | C4: Production Result>Result Adjustment Management | D4: GMES_IM_POM | E4: GMES_IMES_0565 | F4: 재처리 이력 | G4: Reprocessing History | H4: Lịch sử tái xử lý | I4: 0 | J4: TODO | O4: The Webiste UI can not be access
A5: 28 | B5: 생산실적>정보조회 | C5: Production Result>information inquiry | D5: GMES_IM_POM | E5: GMES_IMES_0310_1 | F5: 생산실적 조회(T) | G5: Production Result Inquiry | H5: Tra cứu thành tích sản xuất (T) | I5: 0 | J5: TODO | O5: The Webiste UI can not be access// menu name is wierd
A6: 30 | B6: 생산실적>정보조회 | C6: Production Result>information inquiry | D6: GMES_IM_POM | E6: GMES_IMES_0570 | F6: 이상품 재고 발생 현황 | G6: Status of abnormal product inventory occurrence | H6: Tình trạng phát sinh tồn kho lỗi | I6: 0 | J6: TODO | O6: The Webiste UI can not be access
A7: 33 | B7: 생산실적>수율 | C7: Production Result>Yield Report | D7: GMES_IM_POM | E7: GMES_IMES_0287 | F7: 수율(RTY) 조회 | G7: Yield(RTY) Inquiry | H7: Tra cứu năng suất (RTY) | I7: 0 | J7: TODO | O7: The Webiste UI can not be access
A8: 34 | B8: 생산실적>수율 | C8: Production Result>Yield Report | D8: GMES_IM_POM | E8: GMES_IMES_0288 | F8: 수율(RTY) Report | G8: Yield(RTY) Summary | H8: Báo cáo năng suất (RTY) | I8: 0 | J8: TODO | O8: The Webiste UI can not be access
A9: 35 | B9: 생산실적>수율 | C9: Production Result>Yield Report | D9: GMES_IM_POM | E9: GMES_IMES_0285 | F9: 수율집계 대상 List 조회 | G9: Yield(RTY) Aggregation List | H9: Tra cứu danh sách đối tượng tổng hợp năng suất | I9: 0 | J9: TODO | O9: The Webiste UI can not be access
A10: 36 | B10: 생산실적>수율 | C10: Production Result>Yield Report | D10: GMES_IM_POM | E10: GMES_IMES_0286 | F10: 수율집계대상 변경이력 | G10: Yield Aggregation Target Change History | H10: Lịch sử thay đổi đối tượng tổng hợp năng suất | I10: 0 | J10: TODO | O10: The Webiste UI can not be access
A11: 74 | B11: 시스템관리>사용자관리 | C11: System Manangement>User Management | D11: COMM_FRW | E11: COMM_FRW_0001 | F11: 사용자 | G11: User | H11: Người dùng | I11: 0 | J11: TODO | O11: No Authority
A12: 75 | B12: x | C12: x | D12: GMES_IM_POM | E12: GMES_IMES_8000 | F12: (개발중)네비게이터 | G12: Navigator (In Development) | H12: Điều hướng (Đang phát triển) | I12: 0 | J12: TODO | O12: This screen is done already
A13: 76 | B13: 표준관리 > GMES 운영지표 | C13: 표준관리 > GMES operating indicators | D13: GMES_POM | E13: GMES_IMS_0814 | F13: GMES 운영지표 | G13: GMES Operation Indicators | H13: Chỉ số vận hành GMES | I13: 0 | J13: TODO | O13: The website UI can not be access
A14: 58 | B14: 재고관리>ERP I/F | C14: Inventory Management>ERP I/F | D14: GMES_POM | E14: GMES_IMS_0928 | F14: ERP 기타출고 처리 | G14: ERP Account Transact | H14: Xử lý xuất kho khác ERP | I14: 0 | J14: TODO | K14: Eddie
A15: 62 | B15: 재고관리>ERP I/F | C15: Inventory Management>ERP I/F | D15: GMES_POM | E15: GMES_IMS_0583 | F15: ERP 전표조회 | G15: ERP Transaction History | H15: Tra cứu chứng từ ERP | I15: 0 | J15: TODO | K15: Eddie
A16: 64 | B16: 생산일지>생산팀 관리일지 | C16: Daily Report Management>Production Daily Report | D16: GMES_IM_POM | E16: GMES_IMES_0272 | F16: 일지관리 | G16: Report Management | H16: Quản lý nhật ký | I16: 10 | J16: TODO | K16: Eddie | N16: 80h | O16: 1 grid, 1 search, 2 excel, 3 button
A17: 72 | B17: 협력사일지>협력사 관리일지 | C17: Outsourced Company Daily Report Management>Daily Report Management | D17: GMES_IM_POM | E17: GMES_IMES_0272 | F17: 디에스피 일지관리 | G17: Report Management | H17: Quản lý nhật ký DSP | I17: 0 | J17: TODO | K17: Eddie | O17: This is the same sceen but serve diffenrent purpose and have different KOR name
A18: 21 | B18: 공정관리>소포장관리 | C18: Process Management>Small Packing Management | D18: GMES_IM_POM | E18: GMES_IMES_0802 | F18: 투입손실집계 | G18: Total input loss | H18: Tổng hợp hao hụt đầu vào | I18: 0 | J18: TODO | K18: Eddie
A19: 23 | B19: 생산실적>실적조정 관리 | C19: Production Result>Result Adjustment Management | D19: GMES_IM_POM | E19: GMES_IMES_0306 | F19: 공정회수품 관리 | G19: Process Recovered Goods | H19: Quản lý hàng thu hồi công đoạn | I19: 3 | J19: TODO | K19: Eddie | N19: 40h | O19: Search, 2 Excel
A20: 47 | B20: 재고관리>재고마감 | C20: Inventory Management>inventory closing | D20: GMES_IM_POM | E20: GMES_IMES_2611 | F20: 생산마감 MES/ERP 처리현황 | G20: Production Closing MES/ERP Processing Status | H20: Tình trạng xử lý MES/ERP đóng sản xuất | I20: 0 | J20: TODO | K20: Eddie | N20: 24h | O20: Search, Excel
A21: 53 | B21: 재고관리>ERP I/F | C21: Inventory Management>ERP I/F | D21: GMES_POM | E21: GMES_IMS_0923 | F21: 재고실사 문서생성 | G21: Cycle Count Document | H21: Tạo chứng từ kiểm kê tồn kho | I21: 1 | J21: TODO | K21: Eddie | N21: 24h | O21: Search, Excel, print
A22: 55 | B22: 재고관리>ERP I/F | C22: Inventory Management>ERP I/F | D22: GMES_POM | E22: GMES_IMS_0925 | F22: 재고실사 차이배부 | G22: Distribution Variance | H22: Phân bổ chênh lệch kiểm kê | I22: 0 | J22: TODO | K22: Eddie | N22: 40h
A23: 67 | B23: 생산일지>생산팀 관리일지 | C23: Daily Report Management>Production Daily Report | D23: GMES_IM_POM | E23: GMES_IMES_0275 | F23: 소분량점검 일지 | G23: Subdivision Check Report | H23: Nhật ký kiểm tra khối lượng chia nhỏ | I23: 0 | J23: TODO | K23: Eddie
A24: 69 | B24: 생산일지>생산팀 관리일지 | C24: Daily Report Management>Production Daily Report | D24: GMES_IM_POM | E24: GMES_IMES_0277 | F24: 공정일지[차수] | G24: Process Daily Record [Order] | H24: Nhật ký công đoạn [Ca/Đợt] | I24: 0 | J24: TODO | K24: Eddie
A25: 71 | B25: 협력사일지>협력사 관리일지 | C25: Outsourced Company Daily Report Management>Daily Report Management | D25: GMES_IM_POM | E25: GMES_IMES_0272 | F25: 프로에스컴 일지관리 | G25: Report Management | H25: Quản lý nhật ký Proescom | I25: 0 | J25: TODO | K25: Eddie | O25: This is the same sceen but serve diffenrent purpose and have different KOR name
A26: 77 | B26: 시스템관리>개발자 관리 | C26: System Manangement>Developer Management | D26: GMES_IM_POM | E26: GMES_IMES_4000 | F26: Biz Rule 조회 | G26: Biz Rule query | H26: Tra cứu Biz Rule | I26: 0 | J26: TODO | K26: Eddie
A27: 26 | B27: 생산실적>정보조회 | C27: Production Result>information inquiry | D27: GMES_IM_POM | E27: GMES_IMES_0239 | F27: 소성점검 일지 | G27: RHK Check Report | H27: Nhật ký kiểm tra nung | I27: 0 | J27: TODO | K27: Hughie | N27: 40h | O27: 1 Grid , 1 search, 1 page popup research, excel
A28: 48 | B28: 재고관리>재고마감 | C28: Inventory Management>inventory closing | D28: GMES_IM_POM | E28: GMES_IMES_2612 | F28: 생산마감 | G28: Production Closing | H28: Đóng sản xuất | I28: 9 | J28: TODO | K28: Hughie | N28: 80h | O28: 6 tab 6 grid,
A29: 56 | B29: 재고관리>ERP I/F | C29: Inventory Management>ERP I/F | D29: GMES_POM | E29: GMES_IMS_0926 | F29: 재고실사 ERP반영 | G29: Send Variance to ER | H29: Phản ánh kiểm kê vào ERP | I29: 0 | J29: TODO | K29: Hughie | N29: 40h | O29: 1 grid, search, 5 excel. Query ERP stock-gap disbursement + send difference to ERP (PP0547 SO) + update send flag. 5 BizActors.
A30: 50 | B30: 재고관리>정보조회 | C30: Inventory Management>Information inquiry | D30: GMES_IM_POM | E30: GMES_IMES_0560 | F30: 재고 관리 현황 | G30: Stock list management list | H30: Tình trạng quản lý tồn kho | I30: 6 | J30: TODO | K30: Hughie | N30: 80h | O30: 1 master grid w/ 4 dynamic layouts (Plan/PlanB/NCR/Hold) + tabs. 6 sub-popups (0560_01~06) for abnormal stock/rack mgmt. 6 BizActors + sub-screens.
A31: 52 | B31: 재고관리>ERP I/F | C31: Inventory Management>ERP I/F | D31: GMES_IM_POM | E31: GMES_IMES_0531 | F31: ERP I/F 결과 [이전전기] | G31: ERP I/F [Transfer] | H31: Kết quả I/F ERP [Kỳ trước] | I31: 0 | J31: TODO | K31: Hughie | N31: 24h | O31: 1 grid, search, excel. ERP I/F result [prev period] query only (WIPCLOSE / MOVESTOCK). 3 BizActors.
A32: 924 | B32: 재고관리>ERP I/F | C32: Inventory Management>ERP I/F | D32: GMES_POM | E32: GMES_IMS_0924 | F32: 재고실사 입력 | G32: Cycle Count Entry | H32: Nhập kiểm kê tồn kho | I32: 0 | J32: TODO | K32: Hughie | N32: 40h | O32: 1 grid, search, excel, print. Cycle-count entry: check close status + get month stock + update close result. 4 BizActors.
A33: 70 | B33: 생산일지>정보조회 | C33: Daily Report Management>Information inquiry | D33: GMES_IM_POM | E33: GMES_IMES_0279 | F33: 일지 현황판 | G33: DailyRecord Dashboard | H33: Bảng tình trạng nhật ký | I33: 0 | J33: TODO | K33: Hughie | N33: 40h | O33: 1 grid dashboard, 4 combo, 5 excel. Daily-record dashboard (month/day/week, template, type). 8 BizActors.
A34: 312 | B34: 생산실적>정보조회 | C34: Production Result>information inquiry | D34: GMES_IM_POM | E34: GMES_IMES_0312 | F34: 재처리실적 조회[관리자] | G34: Rework History Inquiry[For Manager] | H34: Tra cứu thành tích tái xử lý [Quản trị] | I34: 1 | J34: TODO | K34: Hughie | N34: 40h | O34: 1 grid, 6 combo search, excel. Rework result inquiry (admin) + 1 detail popup (GMES_IMES_0311_01). 9 BizActors.
A35: 530 | B35: 재고관리>ERP I/F | C35: Inventory Management>ERP I/F | D35: GMES_IM_POM | E35: GMES_IMES_0530 | F35: ERP I/F 결과 [실적] | G35: ERP I/F [Production] | H35: Kết quả I/F ERP [Thành tích] | I35: 0 | J35: TODO | K35: Hughie | N35: 40h | O35: 1 grid, 7 combo search, excel. ERP I/F result [production] + material input + update transfer flag. 12 BizActors.
A36: 57 | B36: 재고관리>ERP I/F | C36: Inventory Management>ERP I/F | D36: GMES_POM | E36: GMES_IMS_0927 | F36: ERP 무상사급차후조정 | G36: ERP Adjust TP Material | H36: Điều chỉnh hồi tố cấp phát miễn phí ERP | I36: 0 | J36: TODO | K36: Hughie | N36: 40h | O36: 2 grids (result + detail), excel. ERP free-supply retroactive adjust, send to ERP (MM0476 SO). 3 BizActors.
A37: 31 | B37: 생산실적>정보조회 | C37: Production Result>information inquiry | D37: GMES_IM_POM | E37: GMES_IMES_0257 | F37: DataLake 지표 | G37: Yield(RTY) Change Action Management | H37: Chỉ số DataLake | I37: 0 | J37: TODO | K37: Hughie | N37: 80h | O37: 7 grids, 2 tabs. DataLake indicators w/ dynamic DA_SEL_FN_DL_* biz. 3 combo BizActors + dynamic FN calls.
A38: 581 | B38: 재고관리>ERP I/F | C38: Inventory Management>ERP I/F | D38: GMES_POM | E38: GMES_IMS_0581 | F38: ERP 투입조정 | G38: ERP Adust Input Mtl | H38: Điều chỉnh nhập liệu ERP | I38: 1 | J38: TODO | K38: Hughie | N38: 80h | O38: 2 grids. ERP input adjustment: validate + send + register WIP-close move (v2). 1 popup (GMES_COM_0021). 9 BizActors.
A39: 63 | B39: 재고관리>ERP I/F | C39: Inventory Management>ERP I/F | D39: GMES_POM | E39: 585 | F39: ERP 시점재고 I/F 이력조회 | G39: ERP point-in-time inventory I/F history inquiry | H39: Tra cứu lịch sử I/F tồn kho theo thời điểm ERP | I39: 0 | J39: TODO | K39: Hughie | N39: 40h | O39: 2 grids (history + total/count), 3 combo, 11 excel. ERP point-in-time inventory I/F history inquiry. 4-5 BizActors.
A40: 38 | B40: 물류관리>물류이동 | C40: Logistics Management>Transfer | D40: GMES_IM_POM | E40: GMES_IMES_0423 | F40: 자동창고 I/F 조회 | G40: Automatic warehouse I/F inquiry | H40: Tra cứu I/F kho tự động | I40: 1 | J40: TODO | K40: Jack | N40: 24h | O40: Search(7 Field), Excel, 1 popup
...

Sheet Tracking
A1: CONVERT TRACKING — Chi tiết 34 màn
A2: INFOMATION | G2: Statistics by Each Step (B1 → B6) | M2: Status | O2: Time | S2: Document / LINK
A3: No | B3: Phase | C3: Module Group | D3: Screen ID | E3: Screen Name (Ko) | F3: Assignee | G3: B1 Verify menu | H3: B2 Load page | I3: B3 Extract BizID | J3: B4 Trace tables | K3: B5 Request sent | L3: B6 Data ready | M3: Discovery Progress | N3: Overall State | O3: Discovery started | P3: Discovery done | Q3: Req sent date | R3: Data received | S3: BizIDs found | T3: Tables needed | U3: Note / Blockers
A4: 1 | F4: Vint | G4: Not Started | H4: Not Started | I4: Not Started | J4: Not Started | K4: Not Started | L4: Not Started | M4: =IFERROR(COUNTIF(G4:L4,"Done")/(6-COUNTIF(G4:L4,"N/A")),0) | N4: =IF(COUNTIF(G4:L4,"Blocked")>0,"Blocked",IF(COUNTIF(G4:L4,"Done")+COUNTIF(G4:L4,"N/A")=6,"Data Ready",IF(AND(K4="Done",L4<>"Done"),"Data Requested",IF(COUNTIF(G4:L4,"In Progress")+COUNTIF(G4:L4,"Done")>0,"Discovery","Backlog"))))
A5: 2 | F5: Vint | G5: Not Started | H5: Not Started | I5: Not Started | J5: Not Started | K5: Not Started | L5: Not Started | M5: =IFERROR(COUNTIF(G5:L5,"Done")/(6-COUNTIF(G5:L5,"N/A")),0) | N5: =IF(COUNTIF(G5:L5,"Blocked")>0,"Blocked",IF(COUNTIF(G5:L5,"Done")+COUNTIF(G5:L5,"N/A")=6,"Data Ready",IF(AND(K5="Done",L5<>"Done"),"Data Requested",IF(COUNTIF(G5:L5,"In Progress")+COUNTIF(G5:L5,"Done")>0,"Discovery","Backlog"))))
A6: 3 | F6: Vint | G6: Not Started | H6: Not Started | I6: Not Started | J6: Not Started | K6: Not Started | L6: Not Started | M6: =IFERROR(COUNTIF(G6:L6,"Done")/(6-COUNTIF(G6:L6,"N/A")),0) | N6: =IF(COUNTIF(G6:L6,"Blocked")>0,"Blocked",IF(COUNTIF(G6:L6,"Done")+COUNTIF(G6:L6,"N/A")=6,"Data Ready",IF(AND(K6="Done",L6<>"Done"),"Data Requested",IF(COUNTIF(G6:L6,"In Progress")+COUNTIF(G6:L6,"Done")>0,"Discovery","Backlog"))))
A7: 4 | F7: Vint | G7: Not Started | H7: Not Started | I7: Not Started | J7: Not Started | K7: Not Started | L7: Not Started | M7: =IFERROR(COUNTIF(G7:L7,"Done")/(6-COUNTIF(G7:L7,"N/A")),0) | N7: =IF(COUNTIF(G7:L7,"Blocked")>0,"Blocked",IF(COUNTIF(G7:L7,"Done")+COUNTIF(G7:L7,"N/A")=6,"Data Ready",IF(AND(K7="Done",L7<>"Done"),"Data Requested",IF(COUNTIF(G7:L7,"In Progress")+COUNTIF(G7:L7,"Done")>0,"Discovery","Backlog"))))
A8: 5 | F8: Vint | G8: Not Started | H8: Not Started | I8: Not Started | J8: Not Started | K8: Not Started | L8: Not Started | M8: =IFERROR(COUNTIF(G8:L8,"Done")/(6-COUNTIF(G8:L8,"N/A")),0) | N8: =IF(COUNTIF(G8:L8,"Blocked")>0,"Blocked",IF(COUNTIF(G8:L8,"Done")+COUNTIF(G8:L8,"N/A")=6,"Data Ready",IF(AND(K8="Done",L8<>"Done"),"Data Requested",IF(COUNTIF(G8:L8,"In Progress")+COUNTIF(G8:L8,"Done")>0,"Discovery","Backlog"))))
A9: 6 | F9: Vint | G9: Not Started | H9: Not Started | I9: Not Started | J9: Not Started | K9: Not Started | L9: Not Started | M9: =IFERROR(COUNTIF(G9:L9,"Done")/(6-COUNTIF(G9:L9,"N/A")),0) | N9: =IF(COUNTIF(G9:L9,"Blocked")>0,"Blocked",IF(COUNTIF(G9:L9,"Done")+COUNTIF(G9:L9,"N/A")=6,"Data Ready",IF(AND(K9="Done",L9<>"Done"),"Data Requested",IF(COUNTIF(G9:L9,"In Progress")+COUNTIF(G9:L9,"Done")>0,"Discovery","Backlog"))))
A10: 7 | F10: Vint | G10: Not Started | H10: Not Started | I10: Not Started | J10: Not Started | K10: Not Started | L10: Not Started | M10: =IFERROR(COUNTIF(G10:L10,"Done")/(6-COUNTIF(G10:L10,"N/A")),0) | N10: =IF(COUNTIF(G10:L10,"Blocked")>0,"Blocked",IF(COUNTIF(G10:L10,"Done")+COUNTIF(G10:L10,"N/A")=6,"Data Ready",IF(AND(K10="Done",L10<>"Done"),"Data Requested",IF(COUNTIF(G10:L10,"In Progress")+COUNTIF(G10:L10,"Done")>0,"Discovery","Backlog"))))
A11: 8 | F11: Vint | G11: Not Started | H11: Not Started | I11: Not Started | J11: Not Started | K11: Not Started | L11: Not Started | M11: =IFERROR(COUNTIF(G11:L11,"Done")/(6-COUNTIF(G11:L11,"N/A")),0) | N11: =IF(COUNTIF(G11:L11,"Blocked")>0,"Blocked",IF(COUNTIF(G11:L11,"Done")+COUNTIF(G11:L11,"N/A")=6,"Data Ready",IF(AND(K11="Done",L11<>"Done"),"Data Requested",IF(COUNTIF(G11:L11,"In Progress")+COUNTIF(G11:L11,"Done")>0,"Discovery","Backlog"))))
A12: 9 | F12: Vint | G12: Not Started | H12: Not Started | I12: Not Started | J12: Not Started | K12: Not Started | L12: Not Started | M12: =IFERROR(COUNTIF(G12:L12,"Done")/(6-COUNTIF(G12:L12,"N/A")),0) | N12: =IF(COUNTIF(G12:L12,"Blocked")>0,"Blocked",IF(COUNTIF(G12:L12,"Done")+COUNTIF(G12:L12,"N/A")=6,"Data Ready",IF(AND(K12="Done",L12<>"Done"),"Data Requested",IF(COUNTIF(G12:L12,"In Progress")+COUNTIF(G12:L12,"Done")>0,"Discovery","Backlog"))))
A13: 10 | F13: Vint | G13: Not Started | H13: Not Started | I13: Not Started | J13: Not Started | K13: Not Started | L13: Not Started | M13: =IFERROR(COUNTIF(G13:L13,"Done")/(6-COUNTIF(G13:L13,"N/A")),0) | N13: =IF(COUNTIF(G13:L13,"Blocked")>0,"Blocked",IF(COUNTIF(G13:L13,"Done")+COUNTIF(G13:L13,"N/A")=6,"Data Ready",IF(AND(K13="Done",L13<>"Done"),"Data Requested",IF(COUNTIF(G13:L13,"In Progress")+COUNTIF(G13:L13,"Done")>0,"Discovery","Backlog"))))
A14: 11 | F14: Hughie | G14: Not Started | H14: Not Started | I14: Not Started | J14: Not Started | K14: Not Started | L14: Not Started | M14: =IFERROR(COUNTIF(G14:L14,"Done")/(6-COUNTIF(G14:L14,"N/A")),0) | N14: =IF(COUNTIF(G14:L14,"Blocked")>0,"Blocked",IF(COUNTIF(G14:L14,"Done")+COUNTIF(G14:L14,"N/A")=6,"Data Ready",IF(AND(K14="Done",L14<>"Done"),"Data Requested",IF(COUNTIF(G14:L14,"In Progress")+COUNTIF(G14:L14,"Done")>0,"Discovery","Backlog"))))
A15: 12 | F15: Hughie | G15: Not Started | H15: Not Started | I15: Not Started | J15: Not Started | K15: Not Started | L15: Not Started | M15: =IFERROR(COUNTIF(G15:L15,"Done")/(6-COUNTIF(G15:L15,"N/A")),0) | N15: =IF(COUNTIF(G15:L15,"Blocked")>0,"Blocked",IF(COUNTIF(G15:L15,"Done")+COUNTIF(G15:L15,"N/A")=6,"Data Ready",IF(AND(K15="Done",L15<>"Done"),"Data Requested",IF(COUNTIF(G15:L15,"In Progress")+COUNTIF(G15:L15,"Done")>0,"Discovery","Backlog"))))
... A37: 34 | F37: Eddie | G37: Not Started | H37: Not Started | I37: Not Started | J37: Not Started | K37: Not Started | L37: Not Started | M37: =IFERROR(COUNTIF(G37:L37,"Done")/(6-COUNTIF(G37:L37,"N/A")),0) | N37: =IF(COUNTIF(G37:L37,"Blocked")>0,"Blocked",IF(COUNTIF(G37:L37,"Done")+COUNTIF(G37:L37,"N/A")=6,"Data Ready",IF(AND(K37="Done",L37<>"Done"),"Data Requested",IF(COUNTIF(G37:L37,"In Progress")+COUNTIF(G37:L37,"Done")>0,"Discovery","Backlog"))))

Sheet BizActor List
A1: LIST BIZACTOR ID In 34 Page
A4: PageNumber | B4: Assignee | C4: Screen ID | D4: Page name (VN) | E4: BizActor ID | F4: Prefix | G4: Purpose | H4: Tables | I4: Note
C5: GMES_IMES_0101 | E5: BR_IM_SEL_AREA_CBO, BR_COM_GET_COMMONCODE_CBO, COR_SEL_MATERIALTYPE_CBO, BR_IM_SEL_PRODUCTGROUP_BY_AREA_CBO, BR_IM_SEL_PROCESSSEGMENT_BY_PCSGID_CBO, BR_IM_SEL_EQUIPMENTSEGMENT_BY_PCGSID_CBO, DA_PRD_SEL_WIP_CLOSE_MONTH_OR_DATE
C6: GMES_IMES_0227 | E6: COR_SEL_MATERIALTYPE_CBO, BR_IM_SEL_PRODUCTGROUP_BY_AREA_CBO, BR_IM_SEL_PROCESSSEGMENT_BY_PCSGID_CBO, BR_IM_SEL_EQUIPMENTSEGMENT_BY_PCGSID_CBO, DA_IM_SEL_BLENDER_EQPT_CBO, BR_IM_PRD_GET_WORKODER_LB, BR_COM_GET_COMMONCODE, DA_IM_COM_SEL_COMMONCODE_BY_ATTRIBUTE, BR_IM_PRD_GET_PACK_SCANINFO, BR_IM_PRD_GET_NEW_LOTID, BR_IM_PRD_GET_NEW_LOTID_CUSTOMER, BR_IM_PRD_GET_CUSTOMER_FOR_PACKING, BR_IM_PRD_REG_PACKINGWORKORDER, DA_IM_PRD_SEL_LOT_BLENDER_BOXSAMPLE, DA_IM_BAS_UPD_TB_SFC_PACKINGWORKORDER, DA_IM_PRD_SEL_LOT_BLENDER_BOXLIST, BR_IM_PRD_REG_PACK_CONFIRM_CANCEL, Br_IM_PRD_REG_PACK_CONFIRM_SAMPLE, BR_IM_PRD_REG_PACKINGWORKORDER_DEL, BR_IM_CIM_REG_DELETE_LOT_LB
C7: GMES_IMES_2802 | E7: BR_IM_SEL_AREA_CBO, COR_SEL_MATERIALTYPE_CBO, BR_IM_SEL_PRODUCTGROUP_BY_AREA_CBO, BR_IM_SEL_PROCESSSEGMENT_BY_PCSGID_CBO, BR_IM_SEL_EQUIPMENTSEGMENT_BY_PCGSID_CBO, BR_COM_GET_COMMONCODE_CBO, DA_IM_STK_SEL_SAMPLE_LOT
C10: GMES_IMES_0100_BM | D10: Work Order Inquiry | E10: DA_PRD_SEL_WIP_CLOSE_MONTH_OR_DATE BR_IM_SEL_AREA_CBO | I10: vẫn phân tích màn GMES_IMES_0207
C11: GMES_IMES_0120 | D11: Phiếu yêu cầu công việc đối tác | E11: BR_IM_SEL_AREA_CBO BR_COM_SEL_COMMONCODE_CBO BR_IM_PRD_SEL_COWORKREQUEST DA_BAS_SEL_AREA_CBO ------------------GMES_COM_0006------------ DA_COM_SEL_USERINFO
C12: GMES_IMES_0203 | D12: Material LOT receipt / subdivision (자재입고 · 소분) | E12: BR_IM_REG_MATERIALLOT_SPLIT_CANCEL BR_IM_REG_MATERIALLOT_UPDELETE BR_IM_INF_IQCPASS BR_PRD_SEL_MATERIALLOT_SUPP BR_IM_REG_MATERIALLOT_SUPP DA_IM_PRD_SEL_MATERIALLOT_SUPPLIERMATERIAL_SPLIT DA_IM_PRD_SEL_MTRL_SUBDIVISION_INFO_MLOT_PR BR_CUS_REG_RETURN_MATERIALLOT_NJ BR_IM_REG_MATERIALLOT BR_PRD_SEL_MATERIALLOT_SUPP_LIST DA_PRD_SEL_TRANSORDER_LIST BR_IM_SEL_AREA_CBO DA_IM_COM_SEL_WAREHOUSE_CBO BR_IM_COM_GET_PRODUCTGROUP_AREA_CBO DA_IM_COM_SEL_PROCESS_BY_PCSGID_CBO BR_IM_SEL_EQUIPMENTSEGMENT_BY_PCGSID_CBO BR_IM_COM_GET_EQUIPMENT_ISP_CBO BR_COM_SEL_COMMONCODE_CBO BR_IM_COM_GET_COMMONCODE COR_SEL_LOTTYPE_CBO BR_IM_SEL_PRODUCTGROUP_BY_AREA_CBO BR_IM_SEL_PROCESSSEGMENT_BY_PCSGID_CBO DA_IM_SEL_BLENDER_EQPT_CBO DA_IM_BAS_SEL_AREA_PCSGID_CBO
C13: GMES_IMES_0225 | D13: Small packing (소분 포장) | E13: BR_IM_PRD_SEL_LOT_SMALL_PACKING DA_IM_PRD_SEL_LOT_SMALL_PACKING_BOXLIST BR_IM_COM_REG_CREATE_BOX_MERGE BR_IM_COM_GET_COMMONCODE BR_IM_SEL_AREA_CBO BR_IM_SEL_PRODUCTGROUP_BY_AREA_CBO BR_IM_SEL_PROCESSSEGMENT_BY_PCSGID_CBO BR_IM_SEL_EQUIPMENTSEGMENT_BY_PCGSID_CBO BR_IM_SEL_PROCESS_BY_PCSGID_CBO_M BR_IM_SEL_PROCESS_BY_PCSGID_CBO BR_IM_SEL_EQUIPMENT_SHOP_CBO DA_IM_PRD_SEL_LOT_BLENDER_BOXLIST BR_IM_PRD_REG_LOT_SMALL_PACKING BR_IM_PRD_CHK_PACK_SMALL_PACKING BR_IM_PRD_REG_LOT_SMALL_PACKING_SPLIT BR_IM_PRD_REG_CREATE_BATCH_LB_MTM
C14: GMES_IMES_0226 | D14: Blender / Pilot packing work order | E14: BR_IM_PRD_GET_LOT_BLENDERINFO DA_IM_PRD_SEL_LOT_BLENDER_SAMPLELIST DA_IM_BAS_UPD_TB_SFC_PACKINGWORKORDER_PILOT DA_IM_PRD_SEL_LOT_BLENDER_BOXLIST DA_IM_BAS_SEL_EQUIPMENTATTR_TBL BR_IM_PRD_GET_WORKORDER_LB BR_IM_COM_REG_UPDATE_LOT_LB BR_IM_PRD_REG_PACK_CONFIRM_CANCEL BR_IM_PRD_REG_PACK_CONFIRM_PILOT BR_IM_PRD_REG_PACK_CONFIRM_BOX BR_IM_PRD_REG_PACKINGWORKORDER_DEL BR_IM_COM_REG_DELETE_LOT_LB BR_IM_COM_REG_CREATE_BOX_MERGE BR_IM_COM_GET_LABEL DA_IM_COM_SEL_COMMONCODE_BY_ATTRIBUTE BR_IM_SEL_AREA_CBO BR_IM_SEL_PRODUCTGROUP_BY_AREA_CBO BR_IM_SEL_PROCESSSEGMENT_BY_PCSGID_CBO BR_IM_SEL_EQUIPMENTSEGMENT_BY_PCGSID_CBO BR_IM_SEL_PROCESS_BY_PCSGID_CBO BR_IM_SEL_EQUIPMENT_SHOP_CBO DA_IM_SEL_BLENDER_EQPT_CBO
C15: GMES_IMES_0239 | D15: Equipment daily inspection (LMS) info | E15: DA_IM_SEL_PERSON_BY_EQPT BR_IM_PRD_REG_EQUIPMENTNOTE BR_IM_LMS_GET_EQPT_INSP_DAILY_INFO BR_IM_SEL_EQUIPMENT_SHOP_CBO BR_IM_SEL_AREA_CBO BR_IM_SEL_PRODUCTGROUP_BY_AREA_CBO BR_IM_SEL_PROCESS_BY_PCSGID_CBO BR_IM_SEL_PROCESSSEGMENT_BY_PCSGID_CBO BR_IM_SEL_EQUIPMENTSEGMENT_BY_PCGSID_CBO
C16: GMES_IMES_0240 | D16: Measurement data management | E16: DA_IM_PRD_SEL_WIPCLOSE DA_IM_SEL_PC_LIST DA_IM_BAS_SEL_EQUIPMENTSEGMENT_TBL BR_IM_LMS_SEL_RTY_INFO BR_IM_LMS_REG_MEASURE_DATA BR_IM_PRD_REG_MEASREMENT BR_IM_SEL_AREA_CBO BR_IM_SEL_PRODUCTGROUP_BY_AREA_CBO BR_IM_SEL_PROCESS_BY_PCSGID_CBO BR_IM_SEL_PROCESSSEGMENT_BY_PCSGID_CBO BR_IM_SEL_EQUIPMENTSEGMENT_BY_PCGSID_CBO_FOR_MEASURE BR_CUS_SEL_COMMONCODE_CBO_CMCODE BR_IM_SEL_EQUIPMENT_SHOP_CBO BR_IM_COM_GET_COMMONCODE_CBO BR_IM_PRD_CHK_EXCELDATA
C17: GMES_IMES_2612 | D17: WIP close & ERP posting (재공마감 · ERP 전송) | E17: BR_IM_PRD_UPD_WIPCLOSE_PACK BR_IM_PRD_REG_LOT_PROD_LOTMATERIALHISTORY BR_IM_UPD_WORKORDER_CLOSE BR_IM_PRD_UPD_WIPCLOSE BR_IM_REG_WORKORDER_CLOSE_ERP_SND BR_IM_INF_REG_ERP_MATERIAL_SEND BR_IM_INF_REG_ERP_MOVESTOCK_SEND BR_IM_REG_PACK_CLOSE_ERP_SND BR_IM_REG_WORKORDER_CLOSE_DIV_ERP_SND BR_IM_INF_REG_ERP_PROD_SEND BR_IM_PRD_SEL_WIPCOUNTACTHISTORY_WO_PROD BR_IM_SEL_WORKORDER_WIPCLOSEMONTH BR_IM_PRD_SEL_WIPCOUNT_BY_EQSG BR_IM_PRD_SEL_ERPPOSTRESULT_WIP BR_IM_PRD_SEL_WIPCOUNT_ERPPOSTRESULT_PROD BR_IM_PRD_SEL_WIPCOUNT_ERPPOSTRESULT_WO BR_IM_PRD_SEL_WIPCOUNT_PACK_WIP BR_IM_PRD_SEL_WIPCOUNT_STATE BR_IM_PRD_SEL_WIPCLOSEACTHISTORY_ERP_LIST BR_IM_SEL_AREA_CBO BR_IM_SEL_PRODUCTGROUP_BY_AREA_CBO
C18: GMES_IMES_0205 | D18: Xác nhận nhập nguyên liệu [Đơn vị ngoài] | E18: BR_IM_REG_MATERIALLOT_UPCREATE BR_IM_REG_MATERIALLOT_UPDELETE BR_COM_GET_COMMONCODE_CBO BR_IM_COM_GET_PRODUCTGROUP_AREA_CBO BR_IM_COM_GET_EQSG_BY_PDGR_EXCLUDE BR_IM_COM_GET_EQUIPMENT_ISP_CBO BR_COM_SEL_COMMONCODE_CBO BR_IM_PRD_CHK_MATERIALLOT_WMS_SUPP BR_IM_PRD_SEL_MATERIALLOT_WMS BR_IM_COM_GET_COMMONCODE DA_IM_BAS_SEL_AREA_PCSGID_CBO DA_IM_COM_SEL_PROCESS_BY_PCSGID_CBO DA_IM_COM_SEL_WAREHOUSE_CBO DA_COM_SEL_STORAGELOCATION_BY_EQSGID
C19: GMES_IMES_0228 | D19: Quản lý thành tích đóng gói [Yêu cầu phân tích] | E19: BR_IN_PRD_GET_LOT_BLENDERINFO BR_IM_SEL_AREA_CBO BR_IM_SEL_PRODUCTGROUP_BY_AREA_CBO BR_IM_SEL_PROCESSSEGMENT_BY_PCSGID_CBO BR_IM_SEL_EQUIPMENTSEGMENT_BY_PCGSID_CBO BR_IM_SEL_PROCESS_BY_PCSGID_CBO_M BR_IM_SEL_PROCESS_BY_PCSGID_CBO BR_IM_SEL_EQUIPMENT_SHOP_CBO BR_IM_PRD_GET_WORKORDER_LB BR_IM_COM_REG_UPDATE_LOT_LB BR_IM_PRD_REG_PACK_COMFRM_CANCEL BR_IM_PRD_REG_PACK_COMFRM_PILOT BR_IM_PRD_REG_PACK_COMFRM_BOX_M BR_IM_PRD_REG_PACK_COMFRM_BOX BR_IM_PRD_REG_PACK_PACKINGWORKORDER_DEL BR_IM_PRD_REG_DELETE_LOT_LB BR_IM_PRD_REG_CREATE_BOX_MERGE DA_IM_COM_SEL_COMMONCODE_BY_ATTRIBUTE DA_IM_PRD_SEL_EQPTID_FOR_PACKINGORDER DA_IM_PRD_SEL_LOT_BLENDER_SAMPLELIST DA_IM_BAS_UPU_TB_SFC_PACKINGWORKORDER_PILOT DA_IM_PRD_SEL_LOT_BLENDER_BOXLIST DA_IM_SEL_BLENDER_EQPT_CBO ------------------GMES_COM_0003---------------- DA_PRD_GET_WORKORDER_PARTNO ------------------GMES_IMES_0228_02---------------- BR_IM_PRD_REG_CREATE_CATCH_LB_QCREQUEST BR_IM_PRD_GET_NEW_LOTID_LB_START ------------------GMES_IMES_0228_03---------------- DA_IM_BAS_SEL_LOTATTR_MULITI BR_IM_COM_GET_COMMONCODE BR_IM_SEL_GET_COMMONCODE ------------------GMES_IMES_0220_09---------------- BR_IM_COM_GET_COMMONCODE BR_IM_COM_GET_LABEL_WIPREASONCOLLECT BR_IM_COM_GET_LABLE
C20: GMES_IMES_0272
C21: GMES_IMES_0279 | D21: Bảng tình trạng nhật ký | E21: BR_IM_PRD_SEL_DYRD_DASHBOARD BR_IM_SEL_AREA_CBO BR_IM_SEL_EQUIPMENTSEGMENT_BY_PCGSID_CBO DA_IM_BAS_SEL_DAILYRECORD_TEMPLATE DA_IM_PRD_SEL_DYRD_COMMON DA_IM_BAS_SEL_DAYLYRECORD_MONTH_DAY_WEEK DA_IM_BAS_SEL_DAYLYRECORD_TYPE | F21: BR DA DA DA BR BR COR DA | G21: Query production daily record dashboard Query daily record template Query production daily record common Query daily record month Day Week Query area combobox list Query equipment segment By process-group combobox list Query equipment segment By area Query daily record Type
C22: GMES_IMES_0555 | D22: Tra cứu tình trạng kho | E22: BR_IM_STK_GET_RACK_LOTID BR_IM_SEL_AREA_CBO BR_IM_SEL_PROCESS_BY_PCSGID_CBO BR_IM_SEL_EQUIPMENTSEGMENT_BY_PCGSID_CBO BR_IM_SEL_PROCESSSEGMENT_BY_PCSGID_CBO DA_IM_COM_SEL_COMMONCODE_BY_ATTRIBUTE DA_IM_COM_SEL_WAREHOUSE_CBO
C23: GMES_IMES_2602 | D23: Điều chỉnh bán thành phẩm | E23: BR_IM_SEL_AREA_CBO BR_IM_SEL_PRODUCTGROUP_BY_AREA_CBO BR_IM_SEL_PROCESS_BY_PCGID_CBO BR_IM_SEL_PROCESSSEGMENT_BY_PCSGID_CBO BR_IM_SEL_EQUIPMENTSEGMENT_BY_PCGSID_CBO BR_COM_GET_EQSG_BY_PDGR_EXCLUDE BR_IM_SEL_EQUIPMENT_SHOP_CBO BR_IM_PRD_SEL_EQUIPMENTLOT_LMS_QTY BR_IM_PRD_SEL_EQUIPMENTLOT_WIP_QTY DA_IM_PRD_SEL_EQUIPMENTLOT_SUM DA_BAS_SEL_COMMONCODE_CBO
C24: GMES_IMES_0241 | D24: Tra cứu định mức oxy/bình chứa theo sản phẩm | E24: BR_IM_SEL_AREA_CBO BR_IM_SEL_PRODUCTGROUP_BY_AREA_CBO BR_IM_SEL_PROCESSSEGMENT_BY_PCSGID_CBO BR_IM_SEL_EQUIPMENTSEGMENT_BY_PCGSID_CBO BR_IM_SEL_PROCESS_BY_PCSGID_CBO BR_IM_SEL_EQUIPMENT_SHOP_CBO BR_IM_PRD_SEL_SMALL_PACKING_LOT_HISTORY BR_IM_COM_REG_DELETE_LOT_BOX DA_IM_PRD_SEL_SAMLL_PACKING_LOT_HISTORY
C25: GMES_IMES_0274 | D25: Quản lý hình ảnh hướng dẫn | E25: BR_IM_PRD_REG_DYRD_GID_IMG_IMS BR_IM_PRD_SEL_DYRD_GID_IMG DA_IM_BAS_SEL_DAILYRECORD_TEMPLATE
C26: GMES_IMS_2543 | D26: Tra cứu và hủy MTM | E26: BR_COM_GET_AREA_CBO BR_MTM_CNC_PROC DA_MTM_SEL_HEADER DA_MTM_SEL_DETAIL
C27: GMES_IMES_0803 | D27: Lịch sử đóng gói nhỏ GP | E27: BR_IM_SEL_AREA_CBO BR_IM_SEL_PRODUCTGROUP_BY_AREA_CBO BR_IM_SEL_PROCESS_BY_PCGID_CBO BR_IM_SEL_PROCESSSEGMENT_BY_PCSGID_CBO BR_IM_SEL_EQUIPMENTSEGMENT_BY_PCGSID_CBO BR_IM_SEL_PROCESS_BY_PCSGID_CBO BR_IM_SEL_EQUIPMENT_SHOP_CBO BR_IM_PRD_SEL_SMALL_PACKING_GPBOXLIST
C28: GMES_IMES_0800 | D28: Lịch sử nhập đóng gói nhỏ | E28: BR_IM_SEL_AREA_CBO BR_IM_SEL_PRODUCTGROUP_BY_AREA_CBO BR_IM_SEL_PROCESSSEGMENT_BY_PCSGID_CBO BR_IM_SEL_EQUIPMENTSEGMENT_BY_PCGSID_CBO BR_IM_SEL_PROCESS_BY_PCSGID_CBO BR_IM_SEL_EQUIPMENT_SHOP_CBO BR_IM_PRD_SEL_SMALL_PACKING_INPUT_HISTORY DA_IM_PRD_SEL_SMALL_PACKING_HISTORY
C29: GMES_IMES_0423 | D29: Tra cứu I/F kho tự động | E29: BR_IM_SEL_AREA_CBO DA_IM_BAS_SEL_WAREHOUSEORDER_IF DA_IM_BAS_SEL_TB_EAI_WCS_MOVEHISTORY_R_TRANSRESULT DA_IM_COM_SEL_WAREHOUSE_CBO
C31: GMES_IMES_0257 | D31: Chỉ số DataLake | E31: BR_IM_SEL_AREA_CBO BR_IM_SEL_PRODUCTGROUP_BY_AREA_CBO BR_IM_SEL_EQUIPMENTSEGMENT_BY_PCGSID_CBO | F31: BR BR BR | G31: Query area combobox list Query product group By area combobox list Query equipment segment By process-group combobox list
C32: GMES_IMES_0312 | D32: Tra cứu thành tích tái xử lý [Quản trị] | E32: DA_PRD_SEL_COMMONCODE_REPROC_SUM DA_PRD_SEL_WIP_CLOSE_MONTH_OR_DATE BR_IM_SEL_AREA_CBO BR_IM_SEL_PRODUCTGROUP_BY_AREA_CBO BR_IM_SEL_PROCESS_BY_PCSGID_CBO BR_IM_SEL_PROCESSSEGMENT_BY_PCSGID_CBO BR_IM_SEL_EQUIPMENTSEGMENT_BY_PCGSID_CBO BR_IM_SEL_EQUIPMENT_SHOP_CBO DA_PRD_SEL_MLOT_BY_EQPT_REPROC_SUM_NEW | F32: DA DA BR BR BR BR BR BR DA | G32: Query production common code reprocess Sum Query production WIP closing month Or Date Query area combobox list Query product group By area combobox list Query process By process-seg combobox list Query process segment By process-seg combobox list Query equipment segment By process-group combobox list Query equipment shop combobox list Query production material LOT By equipment reprocess Sum new
C33: GMES_IMES_0530 | D33: Kết quả I/F ERP [Thành tích] | E33: BR_COM_GET_EQUIPMENT_CBO DA_PRD_SEL_EQSGID_PROD_RST BR_COM_GET_PRODUCTGROUP_AREA_CBO DA_BAS_SEL_AREA_CBO BR_COM_GET_COMMONCODE_CBO DA_PRD_SEL_ERP_IF_PROD DA_IM_PRD_SEL_ERP_IF_MATERIAL_INPUT DA_PRD_SEL_ERP_IF_MATERIAL_INPUT BR_INF_REG_ERP_PRODRESULT_BUDAT DA_BAS_SEL_TB_SFC_WIPCLOSEMONTH DA_PRD_UPD_ERP_IF_PROD_TRANSFLAG DA_PRD_UPD_ERP_IF_MATERIAL_INPUT_TRANSFLAG | F33: BR DA BR DA BR DA DA DA BR DA DA DA | G33: Get equipment combobox list Query production equipment-seg production result Rst Get product group area combobox list Query area combobox list Get common code combobox list Query production ERP I/F production result Query production ERP I/F material input Query production ERP I/F material input Register/Insert interface ERP production result posting date Query Tb shop-floor WIP close month Update production ERP I/F production result transfer flag Update production ERP I/F material input transfer flag
C34: GMES_IMES_0531 | D34: Kết quả I/F ERP [Kỳ trước] | E34: BR_COM_GET_COMMONCODE_CBO DA_PRD_SEL_ERP_IF_WIPCLOSE DA_PRD_SEL_ERP_IF_MOVESTOCK | F34: BR DA DA | G34: Get common code combobox list Query production ERP I/F WIP close Query production ERP I/F stock move
C35: GMES_IMES_0560 | D35: Tình trạng quản lý tồn kho | E35: BR_IM_SEL_AREA_CBO DA_IM_COM_SEL_WAREHOUSE_CBO BR_IM_COM_GET_PROD_CLCTITEM BR_IM_STK_GET_RACK_ABNORMAL BR_IM_PRD_SEL_LOT_ABNORMAL_INSPRESULT BR_IM_BAS_REG_ABNORMAL_PROD_LOTNOTE | F35: BR DA BR BR BR BR | G35: Query area combobox list Query warehouse combobox list Get production result collection item Get stock rack abnormal Query production LOT abnormal inspection result Register/Insert abnormal production result LOT note
C36: GMES_IMES_0560_01 | D36: [Popup] Nhập kho / thùng chứa bất thường | E36: BR_IM_SEL_AREA_CBO BR_IM_SEL_PRODUCTGROUP_BY_AREA_CBO BR_IM_SEL_EQUIPMENTSEGMENT_BY_PCGSID_CBO DA_IM_BAS_SEL_PCSGID_BY_EQSGID BR_IM_SEL_PROCESS_BY_PCSGID_CBO DA_IM_BAS_SEL_EQPT_HOPPER DA_IM_BAS_SEL_EQUIPMENTATTR_TBL BR_IM_STK_GET_RACK_ABNORMAL | F36: BR BR BR DA BR DA DA BR | G36: Query area combobox list Query product group By area combobox list Query equipment segment By process-group combobox list Query process-seg By equipment-seg Query process By process-seg combobox list Query equipment hopper Query equipment attribute table Get stock rack abnormal
C37: GMES_IMES_0560_02 | D37: [Popup] Xác nhận hạng mục thu thập bất thường | E37: BR_IM_COM_GET_PROD_CLCTITEM BR_IM_GET_PROD_PRODUCTPROCESSQUALSPEC BR_IM_COM_GET_PROD_CLCTITEM_SPEC BR_IM_REG_ABNORMAL_CLCTITEM_COMMONCODE DA_IM_STK_SEL_RACK_ABNORMAL_CONFIRM | F37: BR BR BR BR DA | G37: Get production result collection item Get production result product-process quality spec Get production result collection item spec Register/Insert abnormal collection item common code Query stock rack abnormal confirm
C38: GMES_IMES_0560_03 | D38: [Popup] Mã chung hạng mục thu thập bất thường | E38: BR_IM_COM_GET_PROD_CLCTITEM BR_IM_REG_ABNORMAL_CLCTITEM_COMMONCODE | F38: BR BR | G38: Get production result collection item Register/Insert abnormal collection item common code
C39: GMES_IMES_0560_04 | D39: [Popup] Rack bất thường | E39: BR_IM_STK_GET_RACK_ABNORMAL DA_IM_SEL_AREA_CBO | F39: BR DA | G39: Get stock rack abnormal Query area combobox list
C40: GMES_IMES_0560_05 | D40: [Popup] Tính toán LOT bất thường | E40: DA_IM_BAS_SEL_PROD_CLCTITEM BR_IM_PRD_SEL_LOT_ABNORMAL_CALC | F40: DA BR | G40: Query production result collection item Query production LOT abnormal calculation
C41: GMES_IMES_0560_06 | D41: [Popup] Ghi chú LOT sản phẩm bất thường | E41: DA_IM_STK_SEL_RACK_ABNORMAL_CONFIRM BR_IM_BAS_REG_ABNORMAL_PROD_LOTNOTE | F41: DA BR | G41: Query stock rack abnormal confirm Register/Insert abnormal production result LOT note
C42: GMES_IMS_0581 | D42: Điều chỉnh nhập liệu ERP | E42: BR_COM_GET_MULTI_CLOSING_CBO BR_COM_GET_STOCKLOCATION_AREAID_CBO DA_PRD_SEL_ERP_INPUT_ADJUST DA_PRD_GET_WORKORDER_INFO_COMMON_2 DA_PRD_SEL_MATERIALINFO BR_PRD_ERP_SEND_INPUT_ADJUST BR_PRD_CHK_INPUT_ADJUST BR_PRD_REG_START_MOVE_WIP_V2 BR_PRD_REG_START_MOVE_WIP_CLOSING | F42: BR BR DA DA DA BR BR BR BR | G42: Get multi closing combobox list Get stock location area combobox list Query production ERP input adjustment Get production work order Info common 2 Query production material info Send to ERP production ERP input adjustment Validate production input adjustment Register/Insert production start Move WIP v2 Register/Insert production start Move WIP closing
... C46: GMES_IMS_0927 | D46: Điều chỉnh hồi tố cấp phát miễn phí ERP | E46: DA_PRD_SEL_ERP_POST_RESULT DA_PRD_SEL_ERP_POST_RESULT_DETAIL BR_PRD_SND_SUPPLY_ADJUST_MM0476_SO | F46: DA DA BR | G46: Query production ERP posting result Query production ERP posting result detail Send to ERP production supply adjustment (MM0476) send-out

Sheet Data_Requests
A1: DATA REQUESTS LOG — Tables need insert data
A4: Batch No | B4: Send Date | C4: Menu ID | D4: Tables | E4: Number of Testcase | F4: sender | G4: HQ PIC | H4: Result Date | I4: Rquest Date | J4: Status

Sheet Issues_Log
A1: ISSUES LOG — Blockers, dependencies, follow-up
A3: Issue ID | B3: Detected Date / Date Identified | C3: Screen ID liên quan | D3: Type | E3: Issue Description | F3: Impact | G3: Reported by | H3: Owner | I3: Status | J3: Comment
